/home/ferrazzi/.conda/envs/gpu_venv_lates/lib/python3.8/site-packages/huggingface_hub/utils/_runtime.py:184: UserWarning: Pydantic is installed but cannot be imported. Please check your installation. `huggingface_hub` will default to not using Pydantic. Error message: '{e}'
  warnings.warn(
adapters_list:   0%|          | 0/36 [00:00<?, ?it/s]
Loading checkpoint shards:   0%|          | 0/2 [00:00<?, ?it/s][A
Loading checkpoint shards:  50%|â–ˆâ–ˆâ–ˆâ–ˆâ–ˆ     | 1/2 [00:02<00:02,  2.54s/it][A
Loading checkpoint shards: 100%|â–ˆâ–ˆâ–ˆâ–ˆâ–ˆâ–ˆâ–ˆâ–ˆâ–ˆâ–ˆ| 2/2 [00:03<00:00,  1.45s/it][ALoading checkpoint shards: 100%|â–ˆâ–ˆâ–ˆâ–ˆâ–ˆâ–ˆâ–ˆâ–ˆâ–ˆâ–ˆ| 2/2 [00:03<00:00,  1.61s/it]
adapters_list:   0%|          | 0/36 [00:06<?, ?it/s]
Traceback (most recent call last):
  File "/home/ferrazzi/.conda/envs/gpu_venv_lates/lib/python3.8/site-packages/huggingface_hub/utils/_errors.py", line 286, in hf_raise_for_status
    response.raise_for_status()
  File "/home/ferrazzi/.conda/envs/gpu_venv_lates/lib/python3.8/site-packages/requests/models.py", line 1021, in raise_for_status
    raise HTTPError(http_error_msg, response=self)
requests.exceptions.HTTPError: 401 Client Error: Unauthorized for url: https://huggingface.co/ferrazzipietro/llama-2-7b-chat-hf_adapters_en.layer1_8_torch.bfloat16_16_32_0.05_2_0.0002/resolve/main/adapter_model.safetensors

The above exception was the direct cause of the following exception:

Traceback (most recent call last):
  File "postprocessing_llama.py", line 78, in <module>
    merged_model = PeftModel.from_pretrained(base_model, 
  File "/home/ferrazzi/.conda/envs/gpu_venv_lates/lib/python3.8/site-packages/peft/peft_model.py", line 332, in from_pretrained
    model.load_adapter(model_id, adapter_name, is_trainable=is_trainable, **kwargs)
  File "/home/ferrazzi/.conda/envs/gpu_venv_lates/lib/python3.8/site-packages/peft/peft_model.py", line 629, in load_adapter
    adapters_weights = load_peft_weights(model_id, device=torch_device, **hf_hub_download_kwargs)
  File "/home/ferrazzi/.conda/envs/gpu_venv_lates/lib/python3.8/site-packages/peft/utils/save_and_load.py", line 197, in load_peft_weights
    has_remote_safetensors_file = hub_file_exists(
  File "/home/ferrazzi/.conda/envs/gpu_venv_lates/lib/python3.8/site-packages/peft/utils/hub_utils.py", line 26, in hub_file_exists
    get_hf_file_metadata(url)
  File "/home/ferrazzi/.conda/envs/gpu_venv_lates/lib/python3.8/site-packages/huggingface_hub/utils/_validators.py", line 118, in _inner_fn
    return fn(*args, **kwargs)
  File "/home/ferrazzi/.conda/envs/gpu_venv_lates/lib/python3.8/site-packages/huggingface_hub/file_download.py", line 1631, in get_hf_file_metadata
    r = _request_wrapper(
  File "/home/ferrazzi/.conda/envs/gpu_venv_lates/lib/python3.8/site-packages/huggingface_hub/file_download.py", line 385, in _request_wrapper
    response = _request_wrapper(
  File "/home/ferrazzi/.conda/envs/gpu_venv_lates/lib/python3.8/site-packages/huggingface_hub/file_download.py", line 409, in _request_wrapper
    hf_raise_for_status(response)
  File "/home/ferrazzi/.conda/envs/gpu_venv_lates/lib/python3.8/site-packages/huggingface_hub/utils/_errors.py", line 323, in hf_raise_for_status
    raise RepositoryNotFoundError(message, response) from e
huggingface_hub.utils._errors.RepositoryNotFoundError: 401 Client Error. (Request ID: Root=1-661d5030-4017f79533574a9e34fa4f8b;89a86fd9-3d9a-44a5-9962-4b82be40eadc)

Repository Not Found for url: https://huggingface.co/ferrazzipietro/llama-2-7b-chat-hf_adapters_en.layer1_8_torch.bfloat16_16_32_0.05_2_0.0002/resolve/main/adapter_model.safetensors.
Please make sure you specified the correct `repo_id` and `repo_type`.
If you are trying to access a private or gated repo, make sure you are authenticated.
Invalid username or password.
